<?xml version="1.0" encoding="utf-8"?>
<!-- This URDF was automatically created by SolidWorks to URDF Exporter! Originally created by Stephen Brawner (brawner@gmail.com) 
     Commit Version: 1.6.0-4-g7f85cfe  Build Version: 1.6.7995.38578
     For more information, please see http://wiki.ros.org/sw_urdf_exporter -->
<robot
  name="jetbot.zip">
  <link
    name="base_link">
    <inertial>
      <origin
        xyz="0.00654026944078741 8.3842825998548E-05 -0.0115540240733828"
        rpy="0 0 0" />
      <mass
        value="0.50474037145407" />
      <inertia
        ixx="0.0001"
        ixy="0"
        ixz="0"
        iyy="0.0004"
        iyz="0"
        izz="0.0005" />
    </inertial>
    <visual>
      <origin
        xyz="0 0 0"
        rpy="0 0 0" />
      <geometry>
        <mesh
          filename="package://jetbot/meshes/base_link.STL" />
      </geometry>
      <material
        name="">
        <color
          rgba="0.286274509803922 0.662745098039216 0.329411764705882 1" />
      </material>
    </visual>
    <collision>
      <origin
        xyz="0 0 0"
        rpy="0 0 0" />
      <geometry>
        <mesh
          filename="package://jetbot/meshes/base_link.STL" />
      </geometry>
    </collision>
  </link>
  
  <gazebo reference="base_link">
    <mu1>200</mu1>
    <mu2>200</mu2>
    <kp>1000000</kp>
    <kd>1</kd>
  </gazebo>

  <link
    name="rueda_izquierda_link">
    <inertial>
      <origin
        xyz="3.46944695195361E-17 5.55111512312578E-17 -0.111487858827401"
        rpy="0 0 0" />
      <mass
        value="0.11" />
      <inertia
        ixx="0.00002"
        ixy="0"
        ixz="0"
        iyy="0.000002"
        iyz="0"
        izz="0.0001" />
    </inertial>
    <visual>
      <origin
        xyz="0 0 0"
        rpy="0 0 0" />
      <geometry>
        <mesh
          filename="package://jetbot/meshes/rueda_izquierda_link.STL" />
      </geometry>
      <material
        name="">
        <color
          rgba="0.286274509803922 0.662745098039216 0.329411764705882 1" />
      </material>
    </visual>
    <collision>
      <origin
        xyz="0 0 0"
        rpy="0 0 0" />
      <geometry>
        <mesh
          filename="package://jetbot/meshes/rueda_izquierda_link.STL" />
      </geometry>
    </collision>
  </link>
  <joint
    name="rueda_izquierda_joint"
    type="continuous">
    <origin
      xyz="-0.00159534842276889 0.0575771474057684 -0.0259999999999999"
      rpy="-1.5707963267949 0.00323559477416837 0" />
    <parent
      link="base_link" />
    <child
      link="rueda_izquierda_link" />
    <axis
      xyz="0 0 1" />
    <limit
      effort="100"
      velocity="100" />
    <dynamics
      damping="0.1"
      friction="0.1" />
  </joint>

  <gazebo reference="rueda_izquierda_link">
    <mu1>200</mu1>
    <mu2>200</mu2>
    <kp>1000000</kp>
    <kd>1</kd>
  </gazebo>

  <link
    name="rueda_derecha_link">
    <inertial>
      <origin
        xyz="-3.46944695195361E-17 5.55111512312578E-17 -0.111487858827401"
        rpy="0 0 0" />
      <mass
        value="0.11" />
      <inertia
        ixx="0.00002"
        ixy="0"
        ixz="0"
        iyy="0.00002"
        iyz="0"
        izz="0.0001" />
    </inertial>
    <visual>
      <origin
        xyz="0 0 0"
        rpy="0 0 0" />
      <geometry>
        <mesh
          filename="package://jetbot/meshes/rueda_derecha_link.STL" />
      </geometry>
      <material
        name="">
        <color
          rgba="0.286274509803922 0.662745098039216 0.329411764705882 1" />
      </material>
    </visual>
    <collision>
      <origin
        xyz="0 0 0"
        rpy="0 0 0" />
      <geometry>
        <mesh
          filename="package://jetbot/meshes/rueda_derecha_link.STL" />
      </geometry>
    </collision>
  </link>

  <gazebo reference="rueda_derecha_link">
    <mu1>200</mu1>
    <mu2>200</mu2>
    <kp>1000000</kp>
    <kd>1</kd>
  </gazebo>

  <joint
    name="rueda_derecha_joint"
    type="continuous">
    <origin
      xyz="-0.00159534842276885 -0.0574179141205974 -0.026"
      rpy="1.5707963267949 0.00323559477416897 0" />
    <parent
      link="base_link" />
    <child
      link="rueda_derecha_link" />
    <axis
      xyz="0 0 1" />
    <limit
      effort="100"
      velocity="100" />
    <dynamics
      damping="0.1"
      friction="0.1" />
  </joint>

  <link
    name="subir_link">
    <inertial>
      <origin
        xyz="-0.0112360433284504 1.86777337999322E-05 0.0218014538142358"
        rpy="0 0 0" />
      <mass
        value="0.1273663857179312" />
      <inertia
        ixx="2.84948866223219E-03"
        ixy="1.10924267812716E-03"
        ixz="6.06486494340449E-03"
        iyy="2.44457860376768E-03"
        iyz="-9.62444108911587E-05"
        izz="1.68835801720332E-03" />
    </inertial>
    <visual>
      <origin
        xyz="0 0 0"
        rpy="0 0 0" />
      <geometry>
        <mesh
          filename="package://jetbot/meshes/subir_link.STL" />
      </geometry>
      <material
        name="">
        <color
          rgba="0.286274509803922 0.662745098039216 0.329411764705882 1" />
      </material>
    </visual>
    <collision>
      <origin
        xyz="0 0 0"
        rpy="0 0 0" />
      <geometry>
        <mesh
          filename="package://jetbot/meshes/subir_link.STL" />
      </geometry>
    </collision>
  </link>

  <gazebo reference="subir_link">
    <mu1>0.1</mu1>
    <mu2>0.1</mu2>
    <kp>1000000</kp>
    <kd>1</kd>
  </gazebo>

  <joint
    name="subir_joint"
    type="prismatic">
    <origin
      xyz="0.075406 7.7147E-05 0.083651"
      rpy="0 0 0" />
    <parent
      link="base_link" />
    <child
      link="subir_link" />
    <axis
      xyz="0 0 1" />
    <limit
      lower="-0.045"
      upper="0"
      effort="100"
      velocity="100" />
    <dynamics
      damping="0.1"
      friction="0.1" />
  </joint>
  
  <link
    name="cuello_link">
    <inertial>
      <origin
        xyz="0.000256043952758245 0.000242602809698511 0.004320766121115"
        rpy="0 0 0" />
      <mass
        value="0.1152446218733567" />
      <inertia
        ixx="9.531648938002E-03"
        ixy="0"
        ixz="0"
        iyy="3.61671912523105E-03"
        iyz="0"
        izz="1.13343121190557E-02" />
    </inertial>
    <visual>
      <origin
        xyz="0 0 0"
        rpy="0 0 0" />
      <geometry>
        <mesh
          filename="package://jetbot/meshes/cuello_link.STL" />
      </geometry>
      <material
        name="">
        <color
          rgba="1 1 1 1" />
      </material>
    </visual>
    <collision>
      <origin
        xyz="0 0 0"
        rpy="0 0 0" />
      <geometry>
        <mesh
          filename="package://jetbot/meshes/cuello_link.STL" />
      </geometry>
    </collision>
  </link>
  <joint
    name="cuello_joint"
    type="revolute">
    <origin
      xyz="-0.0192210339441284 -0.000736206693809111 0.0493487604025714"
      rpy="0 0 3.14159265358979" />
    <parent
      link="subir_link" />
    <child
      link="cuello_link" />
    <axis
      xyz="0 0 1" />
    <limit
      lower="-1.5708"
      upper="1.5708" 
      effort="100"
      velocity="100" />
    <dynamics
      damping="0.1"
      friction="0.1" />
  </joint>

  <link
    name="cabeza_link">
    <inertial>
      <origin
        xyz="-0.0058376231114745 -0.0203720592897022 -0.0320469413089303"
        rpy="0 0 0" />
      <mass
        value="0.127124344939099" />
      <inertia
        ixx="9.29041403714559E-03"
        ixy="0"
        ixz="0"
        iyy="9.02758198745204E-03"
        iyz="0"
        izz="2.1595119252841E-03" />
    </inertial>
    <visual>
      <origin
        xyz="0 0 0"
        rpy="0 0 0" />
      <geometry>
        <mesh
          filename="package://jetbot/meshes/cabeza_link.STL" />
      </geometry>
      <material
        name="">
        <color
          rgba="0.286274509803922 0.662745098039216 0.329411764705882 1" />
      </material>
    </visual>
    <collision>
      <origin
        xyz="0 0 0"
        rpy="0 0 0" />
      <geometry>
        <mesh
          filename="package://jetbot/meshes/cabeza_link.STL" />
      </geometry>
    </collision>
  </link>

  <gazebo reference="cabeza_link">
    <mu1>0.1</mu1>
    <mu2>0.1</mu2>
    <kp>1000000</kp>
    <kd>1</kd>
    <material>Gazebo/Yellow</material>
  </gazebo>

  <joint
    name="cabeza_joint"
    type="revolute">
    <origin
      xyz="0.00027896605587166 0.0322637933061906 0.0102106923628102"
      rpy="-1.5707963267949 -0.471467109281761 0" />
    <parent
      link="cuello_link" />
    <child
      link="cabeza_link" />
    <axis
      xyz="0 0 1" />
    <limit
      lower="-0.7"
      upper="0.35" 
      effort="100"
      velocity="100" />
    <dynamics
      damping="0.1"
      friction="0.1" />
  </joint>

    <joint name="camera_optical_joint" type="fixed">
        <parent link="cabeza_link"/>
        <child link="camera_link_optical"/>
        <origin xyz="0.00027896605587166 -0.0322637933061906 0.0102106923628102" 
        rpy="0 0 0"/>
    </joint>

    <link name="camera_link_optical"></link>

    <gazebo reference="cabeza_link">
        <material>Gazebo/Red</material>

        <sensor name="camera" type="camera">
            <pose> 0 0 0 0 0 0 </pose>
            <visualize>true</visualize>
            <update_rate>10</update_rate>
            <camera>
                <horizontal_fov>1.089</horizontal_fov>
                <image>
                    <format>R8G8B8</format>
                    <width>640</width>
                    <height>480</height>
                </image>
                <clip>
                    <near>0.05</near>
                    <far>8.0</far>
                </clip>
            </camera>
            <plugin name="camera_controller" filename="libgazebo_ros_camera.so">
                <frame_name>camera_link_optical</frame_name>
            </plugin>
        </sensor>
    </gazebo>

  <gazebo>
        <plugin name="diff_drive" filename="libgazebo_ros_diff_drive.so">

            <!-- Wheel Information -->
            <left_joint>rueda_izquierda_joint</left_joint>
            <right_joint>rueda_derecha_joint</right_joint>
            <wheel_separation>0.115154295</wheel_separation>
            <wheel_diameter>0.1</wheel_diameter>


            <!-- Limits -->
            <max_wheel_torque>200</max_wheel_torque>
            <max_wheel_acceleration>10.0</max_wheel_acceleration>

            
            <!-- Output -->
            <odometry_frame>odom</odometry_frame>
            <robot_base_frame>base_link</robot_base_frame>

            <publish_odom>true</publish_odom>
            <publish_odom_tf>true</publish_odom_tf>
            <publish_wheel_tf>true</publish_wheel_tf>

        </plugin>
    </gazebo>

</robot>
