<?xml version="1.0" encoding="utf-8"?>
<!-- This URDF was automatically created by SolidWorks to URDF Exporter! Originally created by Stephen Brawner (brawner@gmail.com) 
     Commit Version: 1.6.0-4-g7f85cfe  Build Version: 1.6.7995.38578
     For more information, please see http://wiki.ros.org/sw_urdf_exporter -->
<robot
  name="jetbot">
  <link
    name="base_link">
    <inertial>
      <origin
        xyz="0.0127440831307621 8.71327684406065E-05 -0.000319974915683446"
        rpy="0 0 0" />
      <mass
        value="0.50474037145407" />
      <inertia
        ixx="0.0001"
        ixy="0"
        ixz="0"
        iyy="0.0004"
        iyz="0"
        izz="0.0005" />
    </inertial>
    <visual>
      <origin
        xyz="0 0 0"
        rpy="0 0 0" />
      <geometry>
        <mesh
          filename="package://jetbot/meshes/base_link.STL" />
      </geometry>
      <material
        name="">
        <color
          rgba="0.286274509803922 0.662745098039216 0.329411764705882 1" />
      </material>
    </visual>
    <collision>
      <origin
        xyz="0 0 0"
        rpy="0 0 0" />
      <geometry>
        <mesh
          filename="package://jetbot/meshes/base_link.STL" />
      </geometry>
    </collision>
  </link>

  <gazebo reference="base_link">
    <mu1>200</mu1>
    <mu2>200</mu2>
    <kp>1000000</kp>
    <kd>1</kd>
  </gazebo>

  <link
    name="derecha_arriba_link">
    <inertial>
      <origin
        xyz="-8.0349E-06 7.461E-05 0.0083"
        rpy="0 0 0" />
      <mass
        value="0.008712" />
      <inertia
        ixx="9.339E-03"
        ixy="-3.12E-6"
        ixz="1.690E-5"
        iyy="0"
        iyz="0"
        izz="1.806E-06" />
    </inertial>
    <visual>
      <origin
        xyz="0 0 0"
        rpy="0 0 0" />
      <geometry>
        <mesh
          filename="package://jetbot/meshes/derecha_arriba_link.STL" />
      </geometry>
      <material
        name="">
        <color
          rgba="0.101960784313725 0.101960784313725 0.101960784313725 1" />
      </material>
    </visual>
    <collision>
      <origin
        xyz="0 0 0"
        rpy="0 0 0" />
      <geometry>
        <mesh
          filename="package://jetbot/meshes/derecha_arriba_link.STL" />
      </geometry>
    </collision>
  </link>
  <joint
    name="derecha_arriba_joint"
    type="continuous">
    <origin
      xyz="0.048098 -0.061627 -0.024956"
      rpy="-1.5708 -0.22688 0" />
    <parent
      link="base_link" />
    <child
      link="derecha_arriba_link" />
    <axis
      xyz="0 0 1" />
    <limit
      effort="100"
      velocity="100" />
    <dynamics
      damping="0.1"
      friction="0.1" />
  </joint>

  <gazebo reference="derecha_arriba_link">
    <mu1>200</mu1>
    <mu2>200</mu2>
    <kp>1000000</kp>
    <kd>1</kd>
  </gazebo>

  <link
    name="derecha_abajo_link">
    <inertial>
      <origin
        xyz="0 -0.000347478415716737 0.00735438596528001"
        rpy="0 0 0" />
      <mass
        value="0.0871203991688674" />
      <inertia
        ixx="9.3384E-04"
        ixy="0"
        ixz="0"
        iyy="9.3685E-04"
        iyz="0"
        izz="1.806E-03" />
    </inertial>
    <visual>
      <origin
        xyz="0 0 0"
        rpy="0 0 0" />
      <geometry>
        <mesh
          filename="package://jetbot/meshes/derecha_abajo_link.STL" />
      </geometry>
      <material
        name="">
        <color
          rgba="0.101960784313725 0.101960784313725 0.101960784313725 1" />
      </material>
    </visual>
    <collision>
      <origin
        xyz="0 0 0"
        rpy="0 0 0" />
      <geometry>
        <mesh
          filename="package://jetbot/meshes/derecha_abajo_link.STL" />
      </geometry>
    </collision>
  </link>
  <joint
    name="derecha_abajo_joint"
    type="continuous">
    <origin
      xyz="-0.061638 -0.060627 -0.024684"
      rpy="1.5708 0 3.1416" />
    <parent
      link="base_link" />
    <child
      link="derecha_abajo_link" />
    <axis
      xyz="0 0 1" />
    <limit
      effort="100"
      velocity="100" />
    <dynamics
      damping="0.1"
      friction="0.1" />
  </joint>

  <gazebo reference="derecha_abajo_link">
    <mu1>200</mu1>
    <mu2>200</mu2>
    <kp>1000000</kp>
    <kd>1</kd>
  </gazebo>

  <link
    name="izquierda_arriba_link">
    <inertial>
      <origin
        xyz="0 0.000347478415716751 0.00735438596527999"
        rpy="0 0 0" />
      <mass
        value="0.0087120399168867" />
      <inertia
        ixx="9.338E-03"
        ixy="0"
        ixz="0"
        iyy="9.368E-03"
        iyz="0"
        izz="1.806E-03" />
    </inertial>
    <visual>
      <origin
        xyz="0 0 0"
        rpy="0 0 0" />
      <geometry>
        <mesh
          filename="package://jetbot/meshes/izquierda_arriba_link.STL" />
      </geometry>
      <material
        name="">
        <color
          rgba="0.101960784313725 0.101960784313725 0.101960784313725 1" />
      </material>
    </visual>
    <collision>
      <origin
        xyz="0 0 0"
        rpy="0 0 0" />
      <geometry>
        <mesh
          filename="package://jetbot/meshes/izquierda_arriba_link.STL" />
      </geometry>
    </collision>
  </link>
  <joint
    name="izquierda_arriba_joint"
    type="continuous">
    <origin
      xyz="0.04845 0.060786 -0.024684"
      rpy="-1.5708 0 3.1416" />
    <parent
      link="base_link" />
    <child
      link="izquierda_arriba_link" />
    <axis
      xyz="0 0 1" />
    <limit
      effort="100"
      velocity="100" />
    <dynamics
      damping="0.1"
      friction="0.1" />
  </joint>

  <gazebo reference="izquierda_arriba_link">
    <mu1>200</mu1>
    <mu2>200</mu2>
    <kp>1000000</kp>
    <kd>1</kd>
  </gazebo>

  <link
    name="izquierda_abajo_link">
    <inertial>
      <origin
        xyz="0 0.000347478415716751 0.00735438596527993"
        rpy="0 0 0" />
      <mass
        value="0.0087120399168867" />
      <inertia
        ixx="9.338E-04"
        ixy="0"
        ixz="0"
        iyy="9.368E-04"
        iyz="0"
        izz="1.806E-03" />
    </inertial>
    <visual>
      <origin
        xyz="0 0 0"
        rpy="0 0 0" />
      <geometry>
        <mesh
          filename="package://jetbot/meshes/izquierda_abajo_link.STL" />
      </geometry>
      <material
        name="">
        <color
          rgba="0.101960784313725 0.101960784313725 0.101960784313725 1" />
      </material>
    </visual>
    <collision>
      <origin
        xyz="0 0 0"
        rpy="0 0 0" />
      <geometry>
        <mesh
          filename="package://jetbot/meshes/izquierda_abajo_link.STL" />
      </geometry>
    </collision>
  </link>
  <joint
    name="izquierda_abajo_joint"
    type="continuous">
    <origin
      xyz="-0.061638 0.060786 -0.024684"
      rpy="-1.5708 0 3.1416" />
    <parent
      link="base_link" />
    <child
      link="izquierda_abajo_link" />
    <axis
      xyz="0 0 1" />
    <limit
      effort="100"
      velocity="100" />
    <dynamics
      damping="0.1"
      friction="0.1" />
  </joint>

  <gazebo reference="izquierda_abajo_link">
    <mu1>200</mu1>
    <mu2>200</mu2>
    <kp>1000000</kp>
    <kd>1</kd>
  </gazebo>

  <link
    name="subir_link">
    <inertial>
      <origin
        xyz="0.0112360433284504 -1.86777337999045E-05 0.0218014538142358"
        rpy="0 0 0" />
      <mass
        value="0.0273" />
      <inertia
        ixx="2.84948E-02"
        ixy="1.10924E-05"
        ixz="0"
        iyy="2.4445E-02"
        iyz="9.6244E-05"
        izz="1.688E-02" />
    </inertial>
    <visual>
      <origin
        xyz="0 0 0"
        rpy="0 0 0" />
      <geometry>
        <mesh
          filename="package://jetbot/meshes/subir_link.STL" />
      </geometry>
      <material
        name="">
        <color
          rgba="0.286274509803922 0.662745098039216 0.329411764705882 1" />
      </material>
    </visual>
    <collision>
      <origin
        xyz="0 0 0"
        rpy="0 0 0" />
      <geometry>
        <mesh
          filename="package://jetbot/meshes/subir_link.STL" />
      </geometry>
    </collision>
  </link>

  <gazebo reference="subir_link">
    <mu1>0.1</mu1>
    <mu2>0.1</mu2>
    <kp>1000000</kp>
    <kd>1</kd>
  </gazebo>

  <joint
    name="subir_joint"
    type="prismatic">
    <origin
      xyz="0.075406 7.7147E-05 0.083651"
      rpy="0 0 3.1416" />
    <parent
      link="base_link" />
    <child
      link="subir_link" />
    <axis
      xyz="0 0 1" />
    <limit
      lower="-0.045"
      upper="0"
      effort="100"
      velocity="100" />
    <dynamics
      damping="0.1"
      friction="0.1" />
  </joint>
  <link
    name="cuello_link">
    <inertial>
      <origin
        xyz="0.00025 0.00024 0.0043"
        rpy="0 0 0" />
      <mass
        value="0.0152" />
      <inertia
        ixx="9.531E-03"
        ixy="6.452E-05"
        ixz="0"
        iyy="3.616E-03"
        iyz="0"
        izz="1.133E-02" />
    </inertial>
    <visual>
      <origin
        xyz="0 0 0"
        rpy="0 0 0" />
      <geometry>
        <mesh
          filename="package://jetbot/meshes/cuello_link.STL" />
      </geometry>
      <material
        name="">
        <color
          rgba="1 1 1 1" />
      </material>
    </visual>
    <collision>
      <origin
        xyz="0 0 0"
        rpy="0 0 0" />
      <geometry>
        <mesh
          filename="package://jetbot/meshes/cuello_link.STL" />
      </geometry>
    </collision>
  </link>
  <joint
    name="cuello_joint"
    type="revolute">
    <origin
      xyz="0.0192 0.0007 0.0493"
      rpy="0 0 0" />
    <parent
      link="subir_link" />
    <child
      link="cuello_link" />
    <axis
      xyz="0 0 1" />
    <limit
      lower="-1.5708"
      upper="1.5708" 
      effort="100"
      velocity="100" />
    <dynamics
      damping="0.1"
      friction="0.1" />
  </joint>

  <gazebo reference="cuello_link">
    <mu1>0.1</mu1>
    <mu2>0.1</mu2>
    <kp>1000000</kp>
    <kd>1</kd>
    <material>Gazebo/Yellow</material>
  </gazebo>

  <link
    name="cabeza_link">
    <inertial>
      <origin
        xyz="0.02 -0.00698 0.0320"
        rpy="0 0 0" />
      <mass
        value="0.0127" />
      <inertia
        ixx="9.03564E-03"
        ixy="9.56752-05"
        ixz="6.61592E-06"
        iyy="9.28229E-03"
        iyz="0"
        izz="2.15950E-03" />
    </inertial>
    <visual>
      <origin
        xyz="0 0 0"
        rpy="0 0 0" />
      <geometry>
        <mesh
          filename="package://jetbot/meshes/cabeza_link.STL" />
      </geometry>
      <material
        name="">
        <color
          rgba="0.286274509803922 0.662745098039216 0.329411764705882 1" />
      </material>
    </visual>
    <collision>
      <origin
        xyz="0 0 0"
        rpy="0 0 0" />
      <geometry>
        <mesh
          filename="package://jetbot/meshes/cabeza_link.STL" />
      </geometry>
    </collision>
  </link>

  <gazebo reference="cabeza_link">
    <mu1>0.1</mu1>
    <mu2>0.1</mu2>
    <kp>1000000</kp>
    <kd>1</kd>
    <material>Gazebo/Yellow</material>
  </gazebo>

  <joint
    name="cabeza_joint"
    type="revolute">
    <origin
      xyz="0.00027 0.032264 0.010211"
      rpy="-1.5708 0 -3.1416" />
    <parent
      link="cuello_link" />
    <child
      link="cabeza_link" />
    <axis
      xyz="0 0 1" />
    <limit
      lower="-1.6"
      upper="0.5" 
      effort="100"
      velocity="100" />
    <dynamics
      damping="0.1"
      friction="0.1" />
  </joint>
  <link
    name="camera_link">
    <inertial>
      <origin
        xyz="0 0 -0.0014"
        rpy="0 0 0" />
      <mass
        value="0.0018" />
      <inertia
        ixx="6.135E-03"
        ixy="0"
        ixz="0"
        iyy="1.3635E-03"
        iyz="0"
        izz="1.95E-03" />
    </inertial>
    <visual>
      <origin
        xyz="0 0 0"
        rpy="0 0 0" />
      <geometry>
        <mesh
          filename="package://jetbot/meshes/camera_link.STL" />
      </geometry>
      <material
        name="">
        <color
          rgba="0.792156862745098 0.819607843137255 0.933333333333333 1" />
      </material>
    </visual>
    <collision>
      <origin
        xyz="0 0 0"
        rpy="0 0 0" />
      <geometry>
        <mesh
          filename="package://jetbot/meshes/camera_link.STL" />
      </geometry>
    </collision>
  </link>
  <joint
    name="camera_joint"
    type="fixed">
    <origin
      xyz="0.030723 -0.0098391 0.032"
      rpy="0.33531 1.5708 0" />
    <parent
      link="cabeza_link" />
    <child
      link="camera_link" />
    <axis
      xyz="0 0 0" />
    </joint>

    


    <joint name="camera_optical_joint" type="fixed">
        <parent link="camera_link"/>
        <child link="camera_link_optical"/>
        <origin xyz="1 1 1" rpy="0.3 0.3 0.3"/>
    </joint>

    <link name="camera_link_optical"></link>

    <gazebo reference="camera_link">
        <material>Gazebo/Red</material>

        <sensor name="camera" type="camera">
            <pose> 1 1 1 1 1 1 </pose>
            <visualize>true</visualize>
            <update_rate>10</update_rate>
            <camera>
                <horizontal_fov>1.399</horizontal_fov>
                <image>
                    <format>R8G8B8</format>
                    <width>640</width>
                    <height>480</height>
                </image>
                <clip>
                    <near>0.05</near>
                    <far>300</far>
                </clip>
            </camera>
            <plugin name="camera_controller" filename="libgazebo_ros_camera.so">
                <frame_name>camera_link_optical</frame_name>
            </plugin>
        </sensor>
    </gazebo>

  <gazebo>
        <plugin name="diff_drive" filename="libgazebo_ros_diff_drive.so">

            <!-- Wheel Information -->
            <left_joint>izquierda_arriba_link</left_joint>
            <right_joint>derecha_arriba_link</right_joint>
            <wheel_separation>0.115154295</wheel_separation>
            <wheel_diameter>0.1</wheel_diameter>


            <!-- Limits -->
            <max_wheel_torque>500</max_wheel_torque>
            <max_wheel_acceleration>80.0</max_wheel_acceleration>

            
            <!-- Output -->
            <odometry_frame>odom</odometry_frame>
            <robot_base_frame>base_link</robot_base_frame>

            <publish_odom>true</publish_odom>
            <publish_odom_tf>true</publish_odom_tf>
            <publish_wheel_tf>true</publish_wheel_tf>

        </plugin>
    </gazebo>

</robot>
